Workbook

Sheet Dashboard
A1: GHG Inventory Dashboard
A2: All totals below are formula-driven and only include Scope 3 categories marked 'Included' in Materiality_Screening.
A4: Scope 1 (tCO2e) | B4: =GHG_Calculator!F22
A5: Scope 2 - Location-Based (tCO2e) | B5: =GHG_Calculator!F32
A6: Scope 2 - Market-Based (tCO2e) | B6: =GHG_Calculator!F39
A7: Scope 3, Categories 1-9 (tCO2e, materiality-filtered) | B7: =SUM(GHG_Calculator!F42:F92)
A8: Scope 3, Categories 10-15 (tCO2e) | B8: =Scope3_Hard_Categories!B53
A10: GRAND TOTAL - Location-Based Scope 2 (tCO2e) | B10: =B4+B5+B7+B8
A11: GRAND TOTAL - Market-Based Scope 2 (tCO2e) | B11: =B4+B6+B7+B8
A13: Rows still flagged (unassessed quantity or zero factor)
A14: =COUNTIF(GHG_Calculator!G2:G92,"?*") | B14: ="Open the GHG_Calculator tab -> Flag column to see which rows"
A16: Excluded / Not Applicable Scope 3 categories (with reason)
A17: Category | B17: Decision | C17: Justification
A18: =IF(Materiality_Screening!D2<>"Included",Materiality_Screening!B2,"") | B18: =IF(Materiality_Screening!D2<>"Included",Materiality_Screening!D2,"") | C18: =IF(Materiality_Screening!D2<>"Included",Materiality_Screening!E2,"")
A19: =IF(Materiality_Screening!D3<>"Included",Materiality_Screening!B3,"") | B19: =IF(Materiality_Screening!D3<>"Included",Materiality_Screening!D3,"") | C19: =IF(Materiality_Screening!D3<>"Included",Materiality_Screening!E3,"")
A20: =IF(Materiality_Screening!D4<>"Included",Materiality_Screening!B4,"") | B20: =IF(Materiality_Screening!D4<>"Included",Materiality_Screening!D4,"") | C20: =IF(Materiality_Screening!D4<>"Included",Materiality_Screening!E4,"")
A21: =IF(Materiality_Screening!D5<>"Included",Materiality_Screening!B5,"") | B21: =IF(Materiality_Screening!D5<>"Included",Materiality_Screening!D5,"") | C21: =IF(Materiality_Screening!D5<>"Included",Materiality_Screening!E5,"")
A22: =IF(Materiality_Screening!D6<>"Included",Materiality_Screening!B6,"") | B22: =IF(Materiality_Screening!D6<>"Included",Materiality_Screening!D6,"") | C22: =IF(Materiality_Screening!D6<>"Included",Materiality_Screening!E6,"")
A23: =IF(Materiality_Screening!D7<>"Included",Materiality_Screening!B7,"") | B23: =IF(Materiality_Screening!D7<>"Included",Materiality_Screening!D7,"") | C23: =IF(Materiality_Screening!D7<>"Included",Materiality_Screening!E7,"")
A24: =IF(Materiality_Screening!D8<>"Included",Materiality_Screening!B8,"") | B24: =IF(Materiality_Screening!D8<>"Included",Materiality_Screening!D8,"") | C24: =IF(Materiality_Screening!D8<>"Included",Materiality_Screening!E8,"")
A25: =IF(Materiality_Screening!D9<>"Included",Materiality_Screening!B9,"") | B25: =IF(Materiality_Screening!D9<>"Included",Materiality_Screening!D9,"") | C25: =IF(Materiality_Screening!D9<>"Included",Materiality_Screening!E9,"")
A26: =IF(Materiality_Screening!D10<>"Included",Materiality_Screening!B10,"") | B26: =IF(Materiality_Screening!D10<>"Included",Materiality_Screening!D10,"") | C26: =IF(Materiality_Screening!D10<>"Included",Materiality_Screening!E10,"")
A27: =IF(Materiality_Screening!D11<>"Included",Materiality_Screening!B11,"") | B27: =IF(Materiality_Screening!D11<>"Included",Materiality_Screening!D11,"") | C27: =IF(Materiality_Screening!D11<>"Included",Materiality_Screening!E11,"")
A28: =IF(Materiality_Screening!D12<>"Included",Materiality_Screening!B12,"") | B28: =IF(Materiality_Screening!D12<>"Included",Materiality_Screening!D12,"") | C28: =IF(Materiality_Screening!D12<>"Included",Materiality_Screening!E12,"")
A29: =IF(Materiality_Screening!D13<>"Included",Materiality_Screening!B13,"") | B29: =IF(Materiality_Screening!D13<>"Included",Materiality_Screening!D13,"") | C29: =IF(Materiality_Screening!D13<>"Included",Materiality_Screening!E13,"")
... A32: =IF(Materiality_Screening!D16<>"Included",Materiality_Screening!B16,"") | B32: =IF(Materiality_Screening!D16<>"Included",Materiality_Screening!D16,"") | C32: =IF(Materiality_Screening!D16<>"Included",Materiality_Screening!E16,"")
A34: INVENTORY CONFIDENCE — Data Quality Rating (DQR)
A35: DQR scale: 1.0 = Best / Verified primary data. 5.0 = Worst / Unqualified estimate. Composite = AVERAGE of Reliability, Completeness, Temporal, Geographical, Technology per line item.
A36: Average DQR — Scope 1 | C36: =Data_Quality_Scoring!J84
A37: Average DQR — Scope 2 (Loc-Based) | C37: =Data_Quality_Scoring!J85
A38: Average DQR — Scope 2 (Mkt-Based) | C38: =Data_Quality_Scoring!J86
A39: Average DQR — Scope 3 Cat 1–9 | C39: =Data_Quality_Scoring!J87
A40: Average DQR — Scope 3 Cat 10–15 | C40: =Data_Quality_Scoring!J88
A41: OVERALL INVENTORY DQR | C41: =Data_Quality_Scoring!J89
A43: CONFIDENCE BAND | B43: =IF(C41="","⬜ NOT YET SCORED — complete Data_Quality_Scoring tab",IF(C41<=2,"🟢 HIGH — Data is verified and site-specific; suitable for disclosure",IF(C41<=3.5,"🟡 MEDIUM — Mixed confidence; flag for reviewer attention before disclosure","🔴 LOW — Proxy-heavy or unscored; disclose only with explicit caveats")))
A45: ⚠ DISCLAIMER: This workbook produces a screening estimate, not an assured disclosure. The GHG Protocol Corporate Standard and ISO 14064-1 require third-party verification before results are used in public sustainability reports or regulatory submissions. See Cover_Boundary tab for full methodology statement, boundary decisions, and exclusion justifications.

Sheet Cover_Boundary
A1: GHG Emissions Inventory - Boundary & Reporting Basis
A3: 1. Reporting Entity
A4: Company / Facility Name | D4: Legal entity or facility this inventory covers
A5: Reporting Period | D5: e.g. 1 Apr 2025 - 31 Mar 2026
A6: Base Year | D6: REQUIRED for tracking reductions over time - GHG Protocol mandates a fixed base year
A7: Prepared By / Contact
A8: Date of Preparation
A10: 2. Organizational Boundary (choose ONE consolidation approach)
A11: Consolidation Approach | B11: Select one | D11: Determines which facilities/entities are consolidated into this inventory - see GHG Protocol Corporate Standard Ch.3
A12: Entities/Facilities Included | D12: List every facility or subsidiary consolidated under the chosen approach
A13: Entities/Facilities Explicitly Excluded | D13: Document any exclusion and the reason (e.g. divested, immaterial, no operational control)
A15: 3. Operational Boundary (which scopes are covered)
A16: Scope 1 (Direct Emissions) | B16: Included
A17: Scope 2 (Purchased Energy) | B17: Included
A18: Scope 3 (Value Chain) | B18: Included
A19: Scope 3 Categories Excluded (if any) | D19: List category numbers 1-15 excluded and justification - see GHG_Master_Calculator tab for the full category list
A21: 4. Methodology & Standards Applied
A22: Primary Standard | B22: GHG Protocol Corporate Standard + Corporate Value Chain (Scope 3) Standard | D22: e.g. GHG Protocol Corporate Standard + Scope 3 Standard; or ISO 14064-1
A23: GWP Values Used | B23: IPCC AR4 (verify against your disclosure framework's required vintage) | D23: Confirm IPCC Assessment Report vintage - see DB_Master notes column for per-factor citations
A24: Scope 2 Reporting Method | B24: Dual reporting: Location-based + Market-based (see GHG_Master_Calculator) | D24: GHG Protocol Scope 2 Guidance requires BOTH methods where applicable
A26: 5. Assurance Status
A27: Third-Party Verification Status | D27: e.g. Not yet verified / Limited assurance / Reasonable assurance, and by whom
A28: Data Quality Approach | D28: Every line item in GHG_Master_Calculator has a Data Quality tier - see that tab
A30: 6. Materiality & Exclusion Policy
A31: Materiality Threshold | D31: e.g. 5% of total inventory, or an absolute tCO2e cutoff -- state the basis for excluding immaterial sources
A32: Sources Excluded as Immaterial | D32: List any emission source knowingly left out because it falls below the materiality threshold, with rationale
A33: CO2e Conversion Note | D33: Confirm whether Scope 1/2 combustion factors used are CO2-only or full CO2e -- see DB_Master notes column per factor
A35: 7. Version History
A36: Version | B36: Date | C36: Changes
A37: v5 | C37: CO2e labeling correction; materiality/exclusion fields added

Sheet DB_Master
A1: Lookup Key | B1: Emission Factor | C1: Source / Notes | D1: Automation Status | E1: Factor Age / Review Date
A2: Diesel_Fuel | B2: 2.6558 | C2: India GHG Program base CO2 factor (2.64) + ~0.6% CH4/N2O uplift per US EPA GHG Equivalencies methodology (2024) = 2.6558 kgCO2e -- uplift is a documented approximation (CO2 is >99% of combustion CO2e per EPA), not an India-specific measured N2O/CH4 split | D2: Fixed Factor | E2: India GHG Program 2024 / IPCC AR4
A3: Petrol_Fuel | B3: 2.2836 | C3: India GHG Program base CO2 factor (2.27) + ~0.6% CH4/N2O uplift per US EPA GHG Equivalencies methodology (2024) = 2.2836 kgCO2e -- uplift is a documented approximation (CO2 is >99% of combustion CO2e per EPA), not an India-specific measured N2O/CH4 split | D3: Fixed Factor | E3: India GHG Program 2024
A4: CNG_Fuel | B4: 2.686 | C4: India GHG Program base CO2 factor (2.67) + ~0.6% CH4/N2O uplift per US EPA GHG Equivalencies methodology (2024) = 2.686 kgCO2e -- uplift is a documented approximation (CO2 is >99% of combustion CO2e per EPA), not an India-specific measured N2O/CH4 split | D4: Fixed Factor
A5: LPG_Commercial | B5: 2.9979 | C5: India GHG Program base CO2 factor (2.98) + ~0.6% CH4/N2O uplift per US EPA GHG Equivalencies methodology (2024) = 2.9979 kgCO2e -- uplift is a documented approximation (CO2 is >99% of combustion CO2e per EPA), not an India-specific measured N2O/CH4 split | D5: Fixed Factor | E5: India GHG Program 2024
A6: Coal_Indian | B6: 1.9919 | C6: India GHG Program base CO2 factor (1.98) + ~0.6% CH4/N2O uplift per US EPA GHG Equivalencies methodology (2024) = 1.9919 kgCO2e -- uplift is a documented approximation (CO2 is >99% of combustion CO2e per EPA), not an India-specific measured N2O/CH4 split | D6: Fixed Factor | E6: India GHG Program 2024
A7: Furnace_Oil | B7: 3.1186 | C7: India GHG Program base CO2 factor (3.1) + ~0.6% CH4/N2O uplift per US EPA GHG Equivalencies methodology (2024) = 3.1186 kgCO2e -- uplift is a documented approximation (CO2 is >99% of combustion CO2e per EPA), not an India-specific measured N2O/CH4 split | D7: Fixed Factor | E7: India GHG Program 2024 + EPA uplift 2024
A8: Natural_Gas | B8: 1.8913 | C8: India GHG Program base CO2 factor (1.88) + ~0.6% CH4/N2O uplift per US EPA GHG Equivalencies methodology (2024) = 1.8913 kgCO2e -- uplift is a documented approximation (CO2 is >99% of combustion CO2e per EPA), not an India-specific measured N2O/CH4 split | D8: Fixed Factor | E8: India GHG Program 2024 + EPA uplift 2024
A9: Acetylene_Welding | B9: 3.4003 | C9: India GHG Program base CO2 factor (3.38) + ~0.6% CH4/N2O uplift per US EPA GHG Equivalencies methodology (2024) = 3.4003 kgCO2e -- uplift is a documented approximation (CO2 is >99% of combustion CO2e per EPA), not an India-specific measured N2O/CH4 split | D9: Fixed Factor | E9: India GHG Program 2024 + EPA uplift 2024
A10: Fire_Extinguisher_CO2 | B10: 1 | C10: GWP of CO2 = 1, all AR vintages (kgCO2e/kg) | D10: Fixed Factor | E10: IPCC AR4 GWP-100 (2007, stable)
A11: Refrig_R32 | B11: 675 | C11: IPCC AR4 GWP-100 (kgCO2e/kg) -- verify vintage required by your framework | D11: Fixed Factor | E11: IPCC AR4 GWP-100 2007 — verify AR5/AR6 required
A12: Refrig_R410A | B12: 2088 | C12: IPCC AR4 GWP-100 (kgCO2e/kg) -- verify vintage required by your framework | D12: Fixed Factor | E12: IPCC AR4 GWP-100 2007 — verify AR5/AR6 required
A13: Refrig_R22 | B13: 1810 | C13: IPCC AR4 GWP-100 (kgCO2e/kg) -- verify vintage required by your framework | D13: Fixed Factor | E13: IPCC AR4 GWP-100 2007 — verify AR5/AR6 required
A14: Grid_India_CEA | B14: 0.7314 | C14: India GHG Program base CO2 factor (0.727) + ~0.6% CH4/N2O uplift per US EPA GHG Equivalencies methodology (2024) = 0.7314 kgCO2e -- uplift is a documented approximation (CO2 is >99% of combustion CO2e per EPA), not an India-specific measured N2O/CH4 split | D14: Fixed Factor | E14: CEA 2022-23 (published 2024); refresh annually
A15: Grid_MarketBased_Default | B15: 0.7314 | C15: India GHG Program base CO2 factor (0.727) + ~0.6% CH4/N2O uplift per US EPA GHG Equivalencies methodology (2024) = 0.7314 kgCO2e -- uplift is a documented approximation (CO2 is >99% of combustion CO2e per EPA), not an India-specific measured N2O/CH4 split | D15: Fixed Factor | E15: CEA 2022-23 (published 2024); update with supplier data
A16: REC_Backed_Electricity | B16: 0 | C16: Renewable Energy Certificate / PPA-backed electricity, zero-rated per market-based method (kgCO2/kWh) -- confirm REC is unbundled and not double-counted | D16: Fixed Factor | E16: Zero-rated per GHG Protocol S2 Guidance; stable
... A55: Financed_Emissions_Passthrough | B55: 1 | C55: Direct pass-through of reported financed emissions (tCO2e/tCO2e) | D55: Fixed Factor | E55: Direct pass-through; always current
A57: Note: six placeholder factors from v6 (Product_Use_Phase_Energy, Product_EndOfLife, Investment_Equity_Share, Franchise_Estimate, Leased_Asset_Downstream, Processing_Sold_Products_Proxy) have been removed from this table. A single generic factor cannot legitimately represent these — see the Scope3_Hard_Categories tab, where each is replaced with a formula driven by your own company/product data.

Sheet GHG_Calculator
A1: Category / Item | B1: Quantity (Input) | C1: Unit | D1: Emission Factor (live) | E1: Data Quality Tier (set in Data_Quality_Scoring tab) | F1: Result (tCO2e) | G1: Flag
A2: SCOPE 1 - DIRECT EMISSIONS
A3: Category / Item | B3: Quantity (Input) | C3: Unit | D3: Emission Factor (live) | E3: Data Quality | F3: Result (tCO2e) | G3: Flag
A4: Stationary Combustion | B4: 0 | E4: Not Yet Assessed
A5: Diesel Generator (DG Sets) | B5: 0 | C5: Liters | D5: =VLOOKUP("Diesel_Fuel", DB_Master!$A:$B, 2, 0) | E5: =IF(Data_Quality_Scoring!J10="","Not Yet Scored",IF(Data_Quality_Scoring!J10<=2,"High ✓",IF(Data_Quality_Scoring!J10<=3.5,"Medium","Low ⚠"))) | F5: =IF(B5=0,0,(B5*D5)/1000) | G5: =IF(AND(B5>0,Data_Quality_Scoring!J10=""),"Quantity entered but Pedigree not yet scored in Data_Quality_Scoring tab",IF(AND(B5>0,D5=0),"Zero emission factor — check DB_Master slug",""))
A6: Furnace Oil (Boilers) | B6: 0 | C6: Liters | D6: =VLOOKUP("Furnace_Oil", DB_Master!$A:$B, 2, 0) | E6: =IF(Data_Quality_Scoring!J11="","Not Yet Scored",IF(Data_Quality_Scoring!J11<=2,"High ✓",IF(Data_Quality_Scoring!J11<=3.5,"Medium","Low ⚠"))) | F6: =IF(B6=0,0,(B6*D6)/1000) | G6: =IF(AND(B6>0,Data_Quality_Scoring!J11=""),"Quantity entered but Pedigree not yet scored in Data_Quality_Scoring tab",IF(AND(B6>0,D6=0),"Zero emission factor — check DB_Master slug",""))
A7: Natural Gas | B7: 0 | C7: scm | D7: =VLOOKUP("Natural_Gas", DB_Master!$A:$B, 2, 0) | E7: =IF(Data_Quality_Scoring!J12="","Not Yet Scored",IF(Data_Quality_Scoring!J12<=2,"High ✓",IF(Data_Quality_Scoring!J12<=3.5,"Medium","Low ⚠"))) | F7: =IF(B7=0,0,(B7*D7)/1000) | G7: =IF(AND(B7>0,Data_Quality_Scoring!J12=""),"Quantity entered but Pedigree not yet scored in Data_Quality_Scoring tab",IF(AND(B7>0,D7=0),"Zero emission factor — check DB_Master slug",""))
A8: Indian Coal (Boilers) | B8: 0 | C8: kg | D8: =VLOOKUP("Coal_Indian", DB_Master!$A:$B, 2, 0) | E8: =IF(Data_Quality_Scoring!J13="","Not Yet Scored",IF(Data_Quality_Scoring!J13<=2,"High ✓",IF(Data_Quality_Scoring!J13<=3.5,"Medium","Low ⚠"))) | F8: =IF(B8=0,0,(B8*D8)/1000) | G8: =IF(AND(B8>0,Data_Quality_Scoring!J13=""),"Quantity entered but Pedigree not yet scored in Data_Quality_Scoring tab",IF(AND(B8>0,D8=0),"Zero emission factor — check DB_Master slug",""))
A9: Commercial LPG | B9: 0 | C9: kg | D9: =VLOOKUP("LPG_Commercial", DB_Master!$A:$B, 2, 0) | E9: =IF(Data_Quality_Scoring!J14="","Not Yet Scored",IF(Data_Quality_Scoring!J14<=2,"High ✓",IF(Data_Quality_Scoring!J14<=3.5,"Medium","Low ⚠"))) | F9: =IF(B9=0,0,(B9*D9)/1000) | G9: =IF(AND(B9>0,Data_Quality_Scoring!J14=""),"Quantity entered but Pedigree not yet scored in Data_Quality_Scoring tab",IF(AND(B9>0,D9=0),"Zero emission factor — check DB_Master slug",""))
A10: Mobile Combustion (Owned/Leased Vehicles)
A11: Petrol Company Cars | B11: 0 | C11: Liters | D11: =VLOOKUP("Petrol_Fuel", DB_Master!$A:$B, 2, 0) | E11: =IF(Data_Quality_Scoring!J15="","Not Yet Scored",IF(Data_Quality_Scoring!J15<=2,"High ✓",IF(Data_Quality_Scoring!J15<=3.5,"Medium","Low ⚠"))) | F11: =IF(B11=0,0,(B11*D11)/1000) | G11: =IF(AND(B11>0,Data_Quality_Scoring!J15=""),"Quantity entered but Pedigree not yet scored in Data_Quality_Scoring tab",IF(AND(B11>0,D11=0),"Zero emission factor — check DB_Master slug",""))
A12: Diesel Company Vehicles | B12: 0 | C12: Liters | D12: =VLOOKUP("Diesel_Fuel", DB_Master!$A:$B, 2, 0) | E12: =IF(Data_Quality_Scoring!J16="","Not Yet Scored",IF(Data_Quality_Scoring!J16<=2,"High ✓",IF(Data_Quality_Scoring!J16<=3.5,"Medium","Low ⚠"))) | F12: =IF(B12=0,0,(B12*D12)/1000) | G12: =IF(AND(B12>0,Data_Quality_Scoring!J16=""),"Quantity entered but Pedigree not yet scored in Data_Quality_Scoring tab",IF(AND(B12>0,D12=0),"Zero emission factor — check DB_Master slug",""))
A13: CNG Vehicles | B13: 0 | C13: kg | D13: =VLOOKUP("CNG_Fuel", DB_Master!$A:$B, 2, 0) | E13: =IF(Data_Quality_Scoring!J17="","Not Yet Scored",IF(Data_Quality_Scoring!J17<=2,"High ✓",IF(Data_Quality_Scoring!J17<=3.5,"Medium","Low ⚠"))) | F13: =IF(B13=0,0,(B13*D13)/1000) | G13: =IF(AND(B13>0,Data_Quality_Scoring!J17=""),"Quantity entered but Pedigree not yet scored in Data_Quality_Scoring tab",IF(AND(B13>0,D13=0),"Zero emission factor — check DB_Master slug",""))
A14: Fugitive Emissions
A15: Refrigerant Top-up - R-32 | B15: 0 | C15: kg | D15: =VLOOKUP("Refrig_R32", DB_Master!$A:$B, 2, 0) | E15: =IF(Data_Quality_Scoring!J18="","Not Yet Scored",IF(Data_Quality_Scoring!J18<=2,"High ✓",IF(Data_Quality_Scoring!J18<=3.5,"Medium","Low ⚠"))) | F15: =IF(B15=0,0,(B15*D15)/1000) | G15: =IF(AND(B15>0,Data_Quality_Scoring!J18=""),"Quantity entered but Pedigree not yet scored in Data_Quality_Scoring tab",IF(AND(B15>0,D15=0),"Zero emission factor — check DB_Master slug",""))
A16: Refrigerant Top-up - R-410A | B16: 0 | C16: kg | D16: =VLOOKUP("Refrig_R410A", DB_Master!$A:$B, 2, 0) | E16: =IF(Data_Quality_Scoring!J19="","Not Yet Scored",IF(Data_Quality_Scoring!J19<=2,"High ✓",IF(Data_Quality_Scoring!J19<=3.5,"Medium","Low ⚠"))) | F16: =IF(B16=0,0,(B16*D16)/1000) | G16: =IF(AND(B16>0,Data_Quality_Scoring!J19=""),"Quantity entered but Pedigree not yet scored in Data_Quality_Scoring tab",IF(AND(B16>0,D16=0),"Zero emission factor — check DB_Master slug",""))
A17: Refrigerant Top-up - R-22 | B17: 0 | C17: kg | D17: =VLOOKUP("Refrig_R22", DB_Master!$A:$B, 2, 0) | E17: =IF(Data_Quality_Scoring!J20="","Not Yet Scored",IF(Data_Quality_Scoring!J20<=2,"High ✓",IF(Data_Quality_Scoring!J20<=3.5,"Medium","Low ⚠"))) | F17: =IF(B17=0,0,(B17*D17)/1000) | G17: =IF(AND(B17>0,Data_Quality_Scoring!J20=""),"Quantity entered but Pedigree not yet scored in Data_Quality_Scoring tab",IF(AND(B17>0,D17=0),"Zero emission factor — check DB_Master slug",""))
A18: Process Emissions
A19: Acetylene Welding | B19: 0 | C19: kg | D19: =VLOOKUP("Acetylene_Welding", DB_Master!$A:$B, 2, 0) | E19: =IF(Data_Quality_Scoring!J21="","Not Yet Scored",IF(Data_Quality_Scoring!J21<=2,"High ✓",IF(Data_Quality_Scoring!J21<=3.5,"Medium","Low ⚠"))) | F19: =IF(B19=0,0,(B19*D19)/1000) | G19: =IF(AND(B19>0,Data_Quality_Scoring!J21=""),"Quantity entered but Pedigree not yet scored in Data_Quality_Scoring tab",IF(AND(B19>0,D19=0),"Zero emission factor — check DB_Master slug",""))
A20: CO2 Fire Extinguisher Discharge | B20: 0 | C20: kg | D20: =VLOOKUP("Fire_Extinguisher_CO2", DB_Master!$A:$B, 2, 0) | E20: =IF(Data_Quality_Scoring!J22="","Not Yet Scored",IF(Data_Quality_Scoring!J22<=2,"High ✓",IF(Data_Quality_Scoring!J22<=3.5,"Medium","Low ⚠"))) | F20: =IF(B20=0,0,(B20*D20)/1000) | G20: =IF(AND(B20>0,Data_Quality_Scoring!J22=""),"Quantity entered but Pedigree not yet scored in Data_Quality_Scoring tab",IF(AND(B20>0,D20=0),"Zero emission factor — check DB_Master slug",""))
A22: SCOPE 1 TOTAL | F22: =SUM(F3:F21)
A24: SCOPE 2 - PURCHASED ENERGY (Dual Reporting per GHG Protocol Scope 2 Guidance)
A25: Category / Item | B25: Quantity (Input) | C25: Unit | D25: Emission Factor (live) | E25: Data Quality | F25: Result (tCO2e) | G25: Flag
A26: Location-Based Method (grid average emission factor)
A27: Office Electricity - Grid Average | B27: 0 | C27: kWh | D27: =VLOOKUP("Grid_India_CEA", DB_Master!$A:$B, 2, 0) | E27: =IF(Data_Quality_Scoring!J24="","Not Yet Scored",IF(Data_Quality_Scoring!J24<=2,"High ✓",IF(Data_Quality_Scoring!J24<=3.5,"Medium","Low ⚠"))) | F27: =IF(B27=0,0,(B27*D27)/1000) | G27: =IF(AND(B27>0,Data_Quality_Scoring!J24=""),"Quantity entered but Pedigree not yet scored in Data_Quality_Scoring tab",IF(AND(B27>0,D27=0),"Zero emission factor — check DB_Master slug",""))
A28: Factory Electricity - Grid Average | B28: 0 | C28: kWh | D28: =VLOOKUP("Grid_India_CEA", DB_Master!$A:$B, 2, 0) | E28: =IF(Data_Quality_Scoring!J25="","Not Yet Scored",IF(Data_Quality_Scoring!J25<=2,"High ✓",IF(Data_Quality_Scoring!J25<=3.5,"Medium","Low ⚠"))) | F28: =IF(B28=0,0,(B28*D28)/1000) | G28: =IF(AND(B28>0,Data_Quality_Scoring!J25=""),"Quantity entered but Pedigree not yet scored in Data_Quality_Scoring tab",IF(AND(B28>0,D28=0),"Zero emission factor — check DB_Master slug",""))
A29: Warehouse Electricity - Grid Average | B29: 0 | C29: kWh | D29: =VLOOKUP("Grid_India_CEA", DB_Master!$A:$B, 2, 0) | E29: =IF(Data_Quality_Scoring!J26="","Not Yet Scored",IF(Data_Quality_Scoring!J26<=2,"High ✓",IF(Data_Quality_Scoring!J26<=3.5,"Medium","Low ⚠"))) | F29: =IF(B29=0,0,(B29*D29)/1000) | G29: =IF(AND(B29>0,Data_Quality_Scoring!J26=""),"Quantity entered but Pedigree not yet scored in Data_Quality_Scoring tab",IF(AND(B29>0,D29=0),"Zero emission factor — check DB_Master slug",""))
A30: Purchased Steam | B30: 0 | C30: kg | D30: =VLOOKUP("Purchased_Steam", DB_Master!$A:$B, 2, 0) | E30: =IF(Data_Quality_Scoring!J27="","Not Yet Scored",IF(Data_Quality_Scoring!J27<=2,"High ✓",IF(Data_Quality_Scoring!J27<=3.5,"Medium","Low ⚠"))) | F30: =IF(B30=0,0,(B30*D30)/1000) | G30: =IF(AND(B30>0,Data_Quality_Scoring!J27=""),"Quantity entered but Pedigree not yet scored in Data_Quality_Scoring tab",IF(AND(B30>0,D30=0),"Zero emission factor — check DB_Master slug",""))
A32: SCOPE 2 TOTAL (Location-Based) | F32: =SUM(F25:F31)
A34: Market-Based Method (supplier-specific / REC / residual mix)
A35: Office Electricity - Supplier/Residual Mix | B35: 0 | C35: kWh | D35: =VLOOKUP("Grid_MarketBased_Default", DB_Master!$A:$B, 2, 0) | E35: =IF(Data_Quality_Scoring!J29="","Not Yet Scored",IF(Data_Quality_Scoring!J29<=2,"High ✓",IF(Data_Quality_Scoring!J29<=3.5,"Medium","Low ⚠"))) | F35: =IF(B35=0,0,(B35*D35)/1000) | G35: =IF(AND(B35>0,Data_Quality_Scoring!J29=""),"Quantity entered but Pedigree not yet scored in Data_Quality_Scoring tab",IF(AND(B35>0,D35=0),"Zero emission factor — check DB_Master slug",""))
A36: Factory Electricity - Supplier/Residual Mix | B36: 0 | C36: kWh | D36: =VLOOKUP("Grid_MarketBased_Default", DB_Master!$A:$B, 2, 0) | E36: =IF(Data_Quality_Scoring!J30="","Not Yet Scored",IF(Data_Quality_Scoring!J30<=2,"High ✓",IF(Data_Quality_Scoring!J30<=3.5,"Medium","Low ⚠"))) | F36: =IF(B36=0,0,(B36*D36)/1000) | G36: =IF(AND(B36>0,Data_Quality_Scoring!J30=""),"Quantity entered but Pedigree not yet scored in Data_Quality_Scoring tab",IF(AND(B36>0,D36=0),"Zero emission factor — check DB_Master slug",""))
A37: Renewable/REC-Backed Electricity Purchased | B37: 0 | C37: kWh | D37: =VLOOKUP("REC_Backed_Electricity", DB_Master!$A:$B, 2, 0) | E37: Not Yet Assessed | F37: =IF(B37=0,0,(B37*D37)/1000) | G37: =IF(AND(B37>0,E37="Not Yet Assessed"),"Quantity entered but Data Quality not assessed",IF(AND(B37>0,D37=0),"Zero emission factor - check DB_Master",""))
A39: SCOPE 2 TOTAL (Market-Based) | F39: =SUM(F33:F38)
A41: SCOPE 3 - VALUE CHAIN (all 15 GHG Protocol categories)
A42: Category / Item | B42: Quantity (Input) | C42: Unit | D42: Emission Factor (live) | E42: Data Quality | F42: Result (tCO2e) | G42: Flag
A43: Category 1: Purchased Goods & Services
A44: IT / Professional Services (Spend) | B44: 0 | C44: INR | D44: =VLOOKUP("Spend_IT", DB_Master!$A:$B, 2, 0) | E44: =IF(Data_Quality_Scoring!J32="","Not Yet Scored",IF(Data_Quality_Scoring!J32<=2,"High ✓",IF(Data_Quality_Scoring!J32<=3.5,"Medium","Low ⚠"))) | F44: =IF(B44=0,0,(B44*D44)/1000) | G44: =IF(AND(B44>0,Data_Quality_Scoring!J32=""),"Quantity entered but Pedigree not yet scored in Data_Quality_Scoring tab",IF(AND(B44>0,D44=0),"Zero emission factor — check DB_Master slug",""))
A45: Construction / Repairs (Spend) | B45: 0 | C45: INR | D45: =VLOOKUP("Spend_Construction", DB_Master!$A:$B, 2, 0) | E45: =IF(Data_Quality_Scoring!J33="","Not Yet Scored",IF(Data_Quality_Scoring!J33<=2,"High ✓",IF(Data_Quality_Scoring!J33<=3.5,"Medium","Low ⚠"))) | F45: =IF(B45=0,0,(B45*D45)/1000) | G45: =IF(AND(B45>0,Data_Quality_Scoring!J33=""),"Quantity entered but Pedigree not yet scored in Data_Quality_Scoring tab",IF(AND(B45>0,D45=0),"Zero emission factor — check DB_Master slug",""))
A46: Generic Purchased Services (Spend) | B46: 0 | C46: INR | D46: =VLOOKUP("Spend_Generic_Services", DB_Master!$A:$B, 2, 0) | E46: =IF(Data_Quality_Scoring!J34="","Not Yet Scored",IF(Data_Quality_Scoring!J34<=2,"High ✓",IF(Data_Quality_Scoring!J34<=3.5,"Medium","Low ⚠"))) | F46: =IF(B46=0,0,(B46*D46)/1000) | G46: =IF(AND(B46>0,Data_Quality_Scoring!J34=""),"Quantity entered but Pedigree not yet scored in Data_Quality_Scoring tab",IF(AND(B46>0,D46=0),"Zero emission factor — check DB_Master slug",""))
...

Sheet Data_Quality_Scoring
A1: DATA QUALITY SCORING — ISO 14044 Pedigree Matrix
A2: Score each row on the five Pedigree indicators (1=Best, 5=Worst). Composite DQR is auto-averaged. Proxy rows are hard-floored at 3.5. Leave blank ONLY if the row has zero quantity (it will be ignored in rollups).
A3: GHG_Calculator Row | B3: Source Row # (GHG_Calculator) | C3: Scope Tag | D3: Reliability (1=Verified primary → 5=Non-qualified) | E3: Completeness (1=All sites/proc → 5=Very incomplete) | F3: Temporal Corr. (1=≤3 yr → 5=>15 yr) | G3: Geographical Corr. (1=Same area → 5=Unknown) | H3: Technology Corr. (1=Exact process → 5=Unknown) | I3: Composite DQR (auto-averaged) | J3: Effective DQR (proxy-floored)
A4: 1 — Best | D4: Verified data based on measurements / site-specific supplier EPD | E4: All sites / processes fully covered | F4: Data < 3 years old | G4: Same geographical context (India) | H4: Exact technology / process match
A5: 2 | D5: Verified data based on non-site-specific literature | E5: Some data from smaller sites not included | F5: Data 3–6 years old | G5: Same region (South Asia) | H5: Similar technology
A6: 3 | D6: Non-verified data from industry or company | E6: Estimate for <50% of sites/processes | F6: Data 6–10 years old | G6: Global factor applied to regional context | H6: Related process or material
A7: 4 — Proxy floor | D7: Proxy / spend-based / non-industry non-verified | E7: Grossly incomplete estimate | F7: Data 10–15 years old | G7: Factor from different world region | H7: Different but related technology
A8: 5 — Worst | D8: Non-qualified estimate or educated guess | E8: Representativeness unknown | F8: Data > 15 years old | G8: Unknown geographical correlation | H8: Technology unknown
A9: SCOPE 1 — Direct Emissions
A10: Diesel Generator (DG Sets) | B10: 5 | C10: S1 | I10: =IFERROR(IF(AND(D10="",E10="",F10="",G10="",H10=""),"",AVERAGE(D10:H10)),"") | J10: =IF(I10="","",I10)
A11: Furnace Oil (Boilers) | B11: 6 | C11: S1 | I11: =IFERROR(IF(AND(D11="",E11="",F11="",G11="",H11=""),"",AVERAGE(D11:H11)),"") | J11: =IF(I11="","",I11)
A12: Natural Gas | B12: 7 | C12: S1 | I12: =IFERROR(IF(AND(D12="",E12="",F12="",G12="",H12=""),"",AVERAGE(D12:H12)),"") | J12: =IF(I12="","",I12)
A13: Indian Coal (Boilers) | B13: 8 | C13: S1 | I13: =IFERROR(IF(AND(D13="",E13="",F13="",G13="",H13=""),"",AVERAGE(D13:H13)),"") | J13: =IF(I13="","",I13)
A14: Commercial LPG | B14: 9 | C14: S1 | I14: =IFERROR(IF(AND(D14="",E14="",F14="",G14="",H14=""),"",AVERAGE(D14:H14)),"") | J14: =IF(I14="","",I14)
A15: Petrol Company Cars | B15: 11 | C15: S1 | I15: =IFERROR(IF(AND(D15="",E15="",F15="",G15="",H15=""),"",AVERAGE(D15:H15)),"") | J15: =IF(I15="","",I15)
A16: Diesel Company Vehicles | B16: 12 | C16: S1 | I16: =IFERROR(IF(AND(D16="",E16="",F16="",G16="",H16=""),"",AVERAGE(D16:H16)),"") | J16: =IF(I16="","",I16)
A17: CNG Vehicles | B17: 13 | C17: S1 | I17: =IFERROR(IF(AND(D17="",E17="",F17="",G17="",H17=""),"",AVERAGE(D17:H17)),"") | J17: =IF(I17="","",I17)
A18: Refrigerant Top-up - R-32 | B18: 15 | C18: S1 | I18: =IFERROR(IF(AND(D18="",E18="",F18="",G18="",H18=""),"",AVERAGE(D18:H18)),"") | J18: =IF(I18="","",I18)
A19: Refrigerant Top-up - R-410A | B19: 16 | C19: S1 | I19: =IFERROR(IF(AND(D19="",E19="",F19="",G19="",H19=""),"",AVERAGE(D19:H19)),"") | J19: =IF(I19="","",I19)
A20: Refrigerant Top-up - R-22 | B20: 17 | C20: S1 | I20: =IFERROR(IF(AND(D20="",E20="",F20="",G20="",H20=""),"",AVERAGE(D20:H20)),"") | J20: =IF(I20="","",I20)
A21: Acetylene Welding | B21: 19 | C21: S1 | I21: =IFERROR(IF(AND(D21="",E21="",F21="",G21="",H21=""),"",AVERAGE(D21:H21)),"") | J21: =IF(I21="","",I21)
A22: CO2 Fire Extinguisher Discharge | B22: 20 | C22: S1 | I22: =IFERROR(IF(AND(D22="",E22="",F22="",G22="",H22=""),"",AVERAGE(D22:H22)),"") | J22: =IF(I22="","",I22)
A23: SCOPE 2 — Location-Based (Grid Average)
A24: Office Electricity - Grid Average | B24: 27 | C24: S2_LB | I24: =IFERROR(IF(AND(D24="",E24="",F24="",G24="",H24=""),"",AVERAGE(D24:H24)),"") | J24: =IF(I24="","",I24)
A25: Factory Electricity - Grid Average | B25: 28 | C25: S2_LB | I25: =IFERROR(IF(AND(D25="",E25="",F25="",G25="",H25=""),"",AVERAGE(D25:H25)),"") | J25: =IF(I25="","",I25)
A26: Warehouse Electricity - Grid Average | B26: 29 | C26: S2_LB | I26: =IFERROR(IF(AND(D26="",E26="",F26="",G26="",H26=""),"",AVERAGE(D26:H26)),"") | J26: =IF(I26="","",I26)
A27: Purchased Steam | B27: 30 | C27: S2_LB | I27: =IFERROR(IF(AND(D27="",E27="",F27="",G27="",H27=""),"",AVERAGE(D27:H27)),"") | J27: =IF(I27="","",I27)
A28: SCOPE 2 — Market-Based (Supplier / REC)
A29: Office Electricity - Supplier/Residual Mix | B29: 35 | C29: S2_MB | I29: =IFERROR(IF(AND(D29="",E29="",F29="",G29="",H29=""),"",AVERAGE(D29:H29)),"") | J29: =IF(I29="","",I29)
A30: Factory Electricity - Supplier/Residual Mix | B30: 36 | C30: S2_MB | I30: =IFERROR(IF(AND(D30="",E30="",F30="",G30="",H30=""),"",AVERAGE(D30:H30)),"") | J30: =IF(I30="","",I30)
A31: SCOPE 3 — Categories 1–9 (Value Chain)
A32: ⚠ IT / Professional Services (Spend) [PROXY — Reliability capped at 4 min] | B32: 44 | C32: S3_1_9 | I32: =IFERROR(IF(AND(D32="",E32="",F32="",G32="",H32=""),"",AVERAGE(D32:H32)),"") | J32: =IF(I32="","",MAX(I32,3.5))
A33: ⚠ Construction / Repairs (Spend) [PROXY — Reliability capped at 4 min] | B33: 45 | C33: S3_1_9 | I33: =IFERROR(IF(AND(D33="",E33="",F33="",G33="",H33=""),"",AVERAGE(D33:H33)),"") | J33: =IF(I33="","",MAX(I33,3.5))
A34: ⚠ Generic Purchased Services (Spend) [PROXY — Reliability capped at 4 min] | B34: 46 | C34: S3_1_9 | I34: =IFERROR(IF(AND(D34="",E34="",F34="",G34="",H34=""),"",AVERAGE(D34:H34)),"") | J34: =IF(I34="","",MAX(I34,3.5))
A35: Virgin Paper Procurement | B35: 47 | C35: S3_1_9 | I35: =IFERROR(IF(AND(D35="",E35="",F35="",G35="",H35=""),"",AVERAGE(D35:H35)),"") | J35: =IF(I35="","",I35)
A36: Recycled Paper Procurement | B36: 48 | C36: S3_1_9 | I36: =IFERROR(IF(AND(D36="",E36="",F36="",G36="",H36=""),"",AVERAGE(D36:H36)),"") | J36: =IF(I36="","",I36)
A37: Plastic Packaging Procurement | B37: 49 | C37: S3_1_9 | I37: =IFERROR(IF(AND(D37="",E37="",F37="",G37="",H37=""),"",AVERAGE(D37:H37)),"") | J37: =IF(I37="","",I37)
A38: Construction Steel Procurement | B38: 50 | C38: S3_1_9 | I38: =IFERROR(IF(AND(D38="",E38="",F38="",G38="",H38=""),"",AVERAGE(D38:H38)),"") | J38: =IF(I38="","",I38)
A39: Cement Procurement | B39: 51 | C39: S3_1_9 | I39: =IFERROR(IF(AND(D39="",E39="",F39="",G39="",H39=""),"",AVERAGE(D39:H39)),"") | J39: =IF(I39="","",I39)
A40: Laptops Purchased | B40: 53 | C40: S3_1_9 | I40: =IFERROR(IF(AND(D40="",E40="",F40="",G40="",H40=""),"",AVERAGE(D40:H40)),"") | J40: =IF(I40="","",I40)
...

Sheet Materiality_Screening
A1: # | B1: Scope 3 Category | C1: Where it's calculated | D1: Screening Decision | E1: Justification (required if Excluded / N/A)
A2: 1 | B2: Category 1: Purchased Goods & Services | C2: Covered in GHG_Calculator (spend + material proxies) | D2: Included
A3: 2 | B3: Category 2: Capital Goods | C3: Covered in GHG_Calculator | D3: Included
A4: 3 | B4: Category 3: Fuel- and Energy-Related Activities (not in Scope 1/2) | C4: Covered in GHG_Calculator | D4: Included
A5: 4 | B5: Category 4: Upstream Transportation & Distribution | C5: Covered in GHG_Calculator | D5: Included
A6: 5 | B6: Category 5: Waste Generated in Operations | C6: Covered in GHG_Calculator | D6: Included
A7: 6 | B7: Category 6: Business Travel | C7: Covered in GHG_Calculator | D7: Included
A8: 7 | B8: Category 7: Employee Commuting | C8: Covered in GHG_Calculator | D8: Included
A9: 8 | B9: Category 8: Upstream Leased Assets | C9: Covered in GHG_Calculator | D9: Included
A10: 9 | B10: Category 9: Downstream Transportation & Distribution | C10: Covered in GHG_Calculator | D10: Included
A11: 10 | B11: Category 10: Processing of Sold Products | C11: Scope3_Hard_Categories tab | D11: Included
A12: 11 | B12: Category 11: Use of Sold Products | C12: Scope3_Hard_Categories tab | D12: Included
A13: 12 | B13: Category 12: End-of-Life Treatment of Sold Products | C13: Scope3_Hard_Categories tab | D13: Included
... A16: 15 | B16: Category 15: Investments | C16: Scope3_Hard_Categories tab | D16: Included
A18: A category can only be left out of the Dashboard total by an explicit 'Excluded' or 'Not Applicable' decision with a stated reason here — nothing is omitted silently. The Dashboard lists excluded categories with their justification alongside the total.

Sheet Scope3_Hard_Categories
A1: Scope 3 Categories 10-15 — Guided Calculators
A2: These categories can't be estimated from a universal emission factor — each depends on your own product or company data. Fill in the yellow input cells; results calculate live. If you don't have the data yet, go mark the category 'Excluded' in Materiality_Screening with a reason rather than leaving zeros here.
A4: Category 10: Processing of Sold Products
A5: Input | B5: Value | C5: Unit
A6: Units sold requiring further processing | B6: 0 | C6: Units
A7: Downstream processing energy per unit | B7: 0 | C7: kWh/unit
A8: Grid emission factor (auto, from DB_Master) | B8: =VLOOKUP("Grid_India_CEA", DB_Master!$A:$B, 2, 0) | C8: kgCO2e/kWh
A9: RESULT: Category 10 (tCO2e) | B9: =(B6*B7*B8)/1000
A11: Category 11: Use of Sold Products
A12: Input | B12: Value | C12: Unit
A13: Units sold | B13: 0 | C13: Units
A14: In-use energy draw per unit per year | B14: 0 | C14: kWh/unit/year
A15: Expected product lifetime | B15: 0 | C15: Years
A16: Grid emission factor (auto, from DB_Master) | B16: =VLOOKUP("Grid_India_CEA", DB_Master!$A:$B, 2, 0) | C16: kgCO2e/kWh
A17: RESULT: Category 11 (tCO2e) | B17: =(B13*B14*B15*B16)/1000
A19: Category 12: End-of-Life Treatment of Sold Products
A20: Input | B20: Value | C20: Unit
A21: Units sold | B21: 0 | C21: Units
A22: Weight per unit | B22: 0 | C22: kg/unit
A23: Share disposed to landfill | B23: 0 | C23: % (0-1)
A24: Share recycled | B24: 0 | C24: % (0-1)
A25: Share incinerated | B25: 0 | C25: % (0-1)
A26: Check: shares must sum to 100% | B26: =IF(SUM(B23:B25)=1,"OK","FIX: shares do not sum to 100%")
A27: Landfill factor (auto, from DB_Master) | B27: =VLOOKUP("Waste_Landfill", DB_Master!$A:$B, 2, 0) | C27: kgCO2e/kg
A28: Recycling factor (auto, from DB_Master) | B28: =VLOOKUP("Waste_Recycle", DB_Master!$A:$B, 2, 0) | C28: kgCO2e/kg
A29: Incineration factor (auto, from DB_Master) | B29: =VLOOKUP("Waste_Incineration", DB_Master!$A:$B, 2, 0) | C29: kgCO2e/kg
A30: RESULT: Category 12 (tCO2e) | B30: =(B21*B22*(B23*B27+B24*B28+B25*B29))/1000
A32: Category 13: Downstream Leased Assets
A33: Input | B33: Value | C33: Unit
A34: Energy use of assets leased OUT to others (not already in Scope 1/2) | B34: 0 | C34: kWh
A35: Grid emission factor (auto, from DB_Master) | B35: =VLOOKUP("Grid_India_CEA", DB_Master!$A:$B, 2, 0) | C35: kgCO2e/kWh
A36: RESULT: Category 13 (tCO2e) | B36: =(B34*B35)/1000
A38: Category 14: Franchises
A39: Input | B39: Value | C39: Unit
A40: Number of franchises | B40: 0 | C40: Franchises
A41: Average emissions per franchise (company-reported or estimated) | B41: 0 | C41: tCO2e/franchise
A42: RESULT: Category 14 (tCO2e) | B42: =B40*B41
A44: Category 15: Investments
A45: Investee | B45: Investee Emissions (tCO2e) | C45: Equity Share (0-1) | D45: Attributed Emissions (tCO2e)
A46: Investee 1 | B46: 0 | C46: 0 | D46: =B46*C46
...

Sheet _chart_data
A1: Bucket | B1: tCO2e
A2: Scope 1 | B2: =Dashboard!B4
A3: Scope 2 (Location-Based) | B3: =Dashboard!B5
A4: Scope 3 Cat 1-9 | B4: =Dashboard!B7
A5: Scope 3 Cat 10-15 | B5: =Dashboard!B8
